{
 "cells": [
  {
   "cell_type": "code",
   "execution_count": 3,
   "metadata": {},
   "outputs": [
    {
     "name": "stdout",
     "output_type": "stream",
     "text": [
      "INFO:tensorflow:Restoring parameters from ./my_test_model-1000\n"
     ]
    },
    {
     "ename": "NotFoundError",
     "evalue": "Key Variable not found in checkpoint\n\t [[Node: save/RestoreV2 = RestoreV2[dtypes=[DT_FLOAT], _device=\"/job:localhost/replica:0/task:0/cpu:0\"](_arg_save/Const_0_0, save/RestoreV2/tensor_names, save/RestoreV2/shape_and_slices)]]\n\nCaused by op 'save/RestoreV2', defined at:\n  File \"/home/jacek/anaconda3/lib/python3.6/runpy.py\", line 193, in _run_module_as_main\n    \"__main__\", mod_spec)\n  File \"/home/jacek/anaconda3/lib/python3.6/runpy.py\", line 85, in _run_code\n    exec(code, run_globals)\n  File \"/home/jacek/anaconda3/lib/python3.6/site-packages/ipykernel_launcher.py\", line 16, in <module>\n    app.launch_new_instance()\n  File \"/home/jacek/anaconda3/lib/python3.6/site-packages/traitlets/config/application.py\", line 658, in launch_instance\n    app.start()\n  File \"/home/jacek/anaconda3/lib/python3.6/site-packages/ipykernel/kernelapp.py\", line 477, in start\n    ioloop.IOLoop.instance().start()\n  File \"/home/jacek/anaconda3/lib/python3.6/site-packages/zmq/eventloop/ioloop.py\", line 177, in start\n    super(ZMQIOLoop, self).start()\n  File \"/home/jacek/anaconda3/lib/python3.6/site-packages/tornado/ioloop.py\", line 888, in start\n    handler_func(fd_obj, events)\n  File \"/home/jacek/anaconda3/lib/python3.6/site-packages/tornado/stack_context.py\", line 277, in null_wrapper\n    return fn(*args, **kwargs)\n  File \"/home/jacek/anaconda3/lib/python3.6/site-packages/zmq/eventloop/zmqstream.py\", line 440, in _handle_events\n    self._handle_recv()\n  File \"/home/jacek/anaconda3/lib/python3.6/site-packages/zmq/eventloop/zmqstream.py\", line 472, in _handle_recv\n    self._run_callback(callback, msg)\n  File \"/home/jacek/anaconda3/lib/python3.6/site-packages/zmq/eventloop/zmqstream.py\", line 414, in _run_callback\n    callback(*args, **kwargs)\n  File \"/home/jacek/anaconda3/lib/python3.6/site-packages/tornado/stack_context.py\", line 277, in null_wrapper\n    return fn(*args, **kwargs)\n  File \"/home/jacek/anaconda3/lib/python3.6/site-packages/ipykernel/kernelbase.py\", line 283, in dispatcher\n    return self.dispatch_shell(stream, msg)\n  File \"/home/jacek/anaconda3/lib/python3.6/site-packages/ipykernel/kernelbase.py\", line 235, in dispatch_shell\n    handler(stream, idents, msg)\n  File \"/home/jacek/anaconda3/lib/python3.6/site-packages/ipykernel/kernelbase.py\", line 399, in execute_request\n    user_expressions, allow_stdin)\n  File \"/home/jacek/anaconda3/lib/python3.6/site-packages/ipykernel/ipkernel.py\", line 196, in do_execute\n    res = shell.run_cell(code, store_history=store_history, silent=silent)\n  File \"/home/jacek/anaconda3/lib/python3.6/site-packages/ipykernel/zmqshell.py\", line 533, in run_cell\n    return super(ZMQInteractiveShell, self).run_cell(*args, **kwargs)\n  File \"/home/jacek/anaconda3/lib/python3.6/site-packages/IPython/core/interactiveshell.py\", line 2717, in run_cell\n    interactivity=interactivity, compiler=compiler, result=result)\n  File \"/home/jacek/anaconda3/lib/python3.6/site-packages/IPython/core/interactiveshell.py\", line 2821, in run_ast_nodes\n    if self.run_code(code, result):\n  File \"/home/jacek/anaconda3/lib/python3.6/site-packages/IPython/core/interactiveshell.py\", line 2881, in run_code\n    exec(code_obj, self.user_global_ns, self.user_ns)\n  File \"<ipython-input-2-48250861f1ff>\", line 5, in <module>\n    saver = tf.train.import_meta_graph('./model1.meta')\n  File \"/home/jacek/anaconda3/lib/python3.6/site-packages/tensorflow/python/training/saver.py\", line 1686, in import_meta_graph\n    **kwargs)\n  File \"/home/jacek/anaconda3/lib/python3.6/site-packages/tensorflow/python/framework/meta_graph.py\", line 504, in import_scoped_meta_graph\n    producer_op_list=producer_op_list)\n  File \"/home/jacek/anaconda3/lib/python3.6/site-packages/tensorflow/python/framework/importer.py\", line 311, in import_graph_def\n    op_def=op_def)\n  File \"/home/jacek/anaconda3/lib/python3.6/site-packages/tensorflow/python/framework/ops.py\", line 2506, in create_op\n    original_op=self._default_original_op, op_def=op_def)\n  File \"/home/jacek/anaconda3/lib/python3.6/site-packages/tensorflow/python/framework/ops.py\", line 1269, in __init__\n    self._traceback = _extract_stack()\n\nNotFoundError (see above for traceback): Key Variable not found in checkpoint\n\t [[Node: save/RestoreV2 = RestoreV2[dtypes=[DT_FLOAT], _device=\"/job:localhost/replica:0/task:0/cpu:0\"](_arg_save/Const_0_0, save/RestoreV2/tensor_names, save/RestoreV2/shape_and_slices)]]\n",
     "output_type": "error",
     "traceback": [
      "\u001b[0;31m---------------------------------------------------------------------------\u001b[0m",
      "\u001b[0;31mNotFoundError\u001b[0m                             Traceback (most recent call last)",
      "\u001b[0;32m/home/jacek/anaconda3/lib/python3.6/site-packages/tensorflow/python/client/session.py\u001b[0m in \u001b[0;36m_do_call\u001b[0;34m(self, fn, *args)\u001b[0m\n\u001b[1;32m   1138\u001b[0m     \u001b[0;32mtry\u001b[0m\u001b[0;34m:\u001b[0m\u001b[0;34m\u001b[0m\u001b[0m\n\u001b[0;32m-> 1139\u001b[0;31m       \u001b[0;32mreturn\u001b[0m \u001b[0mfn\u001b[0m\u001b[0;34m(\u001b[0m\u001b[0;34m*\u001b[0m\u001b[0margs\u001b[0m\u001b[0;34m)\u001b[0m\u001b[0;34m\u001b[0m\u001b[0m\n\u001b[0m\u001b[1;32m   1140\u001b[0m     \u001b[0;32mexcept\u001b[0m \u001b[0merrors\u001b[0m\u001b[0;34m.\u001b[0m\u001b[0mOpError\u001b[0m \u001b[0;32mas\u001b[0m \u001b[0me\u001b[0m\u001b[0;34m:\u001b[0m\u001b[0;34m\u001b[0m\u001b[0m\n",
      "\u001b[0;32m/home/jacek/anaconda3/lib/python3.6/site-packages/tensorflow/python/client/session.py\u001b[0m in \u001b[0;36m_run_fn\u001b[0;34m(session, feed_dict, fetch_list, target_list, options, run_metadata)\u001b[0m\n\u001b[1;32m   1120\u001b[0m                                  \u001b[0mfeed_dict\u001b[0m\u001b[0;34m,\u001b[0m \u001b[0mfetch_list\u001b[0m\u001b[0;34m,\u001b[0m \u001b[0mtarget_list\u001b[0m\u001b[0;34m,\u001b[0m\u001b[0;34m\u001b[0m\u001b[0m\n\u001b[0;32m-> 1121\u001b[0;31m                                  status, run_metadata)\n\u001b[0m\u001b[1;32m   1122\u001b[0m \u001b[0;34m\u001b[0m\u001b[0m\n",
      "\u001b[0;32m/home/jacek/anaconda3/lib/python3.6/contextlib.py\u001b[0m in \u001b[0;36m__exit__\u001b[0;34m(self, type, value, traceback)\u001b[0m\n\u001b[1;32m     88\u001b[0m             \u001b[0;32mtry\u001b[0m\u001b[0;34m:\u001b[0m\u001b[0;34m\u001b[0m\u001b[0m\n\u001b[0;32m---> 89\u001b[0;31m                 \u001b[0mnext\u001b[0m\u001b[0;34m(\u001b[0m\u001b[0mself\u001b[0m\u001b[0;34m.\u001b[0m\u001b[0mgen\u001b[0m\u001b[0;34m)\u001b[0m\u001b[0;34m\u001b[0m\u001b[0m\n\u001b[0m\u001b[1;32m     90\u001b[0m             \u001b[0;32mexcept\u001b[0m \u001b[0mStopIteration\u001b[0m\u001b[0;34m:\u001b[0m\u001b[0;34m\u001b[0m\u001b[0m\n",
      "\u001b[0;32m/home/jacek/anaconda3/lib/python3.6/site-packages/tensorflow/python/framework/errors_impl.py\u001b[0m in \u001b[0;36mraise_exception_on_not_ok_status\u001b[0;34m()\u001b[0m\n\u001b[1;32m    465\u001b[0m           \u001b[0mcompat\u001b[0m\u001b[0;34m.\u001b[0m\u001b[0mas_text\u001b[0m\u001b[0;34m(\u001b[0m\u001b[0mpywrap_tensorflow\u001b[0m\u001b[0;34m.\u001b[0m\u001b[0mTF_Message\u001b[0m\u001b[0;34m(\u001b[0m\u001b[0mstatus\u001b[0m\u001b[0;34m)\u001b[0m\u001b[0;34m)\u001b[0m\u001b[0;34m,\u001b[0m\u001b[0;34m\u001b[0m\u001b[0m\n\u001b[0;32m--> 466\u001b[0;31m           pywrap_tensorflow.TF_GetCode(status))\n\u001b[0m\u001b[1;32m    467\u001b[0m   \u001b[0;32mfinally\u001b[0m\u001b[0;34m:\u001b[0m\u001b[0;34m\u001b[0m\u001b[0m\n",
      "\u001b[0;31mNotFoundError\u001b[0m: Key Variable not found in checkpoint\n\t [[Node: save/RestoreV2 = RestoreV2[dtypes=[DT_FLOAT], _device=\"/job:localhost/replica:0/task:0/cpu:0\"](_arg_save/Const_0_0, save/RestoreV2/tensor_names, save/RestoreV2/shape_and_slices)]]",
      "\nDuring handling of the above exception, another exception occurred:\n",
      "\u001b[0;31mNotFoundError\u001b[0m                             Traceback (most recent call last)",
      "\u001b[0;32m<ipython-input-3-600d96c737b4>\u001b[0m in \u001b[0;36m<module>\u001b[0;34m()\u001b[0m\n\u001b[1;32m      4\u001b[0m \u001b[0;31m#First let's load meta graph and restore weights\u001b[0m\u001b[0;34m\u001b[0m\u001b[0;34m\u001b[0m\u001b[0m\n\u001b[1;32m      5\u001b[0m \u001b[0msaver\u001b[0m \u001b[0;34m=\u001b[0m \u001b[0mtf\u001b[0m\u001b[0;34m.\u001b[0m\u001b[0mtrain\u001b[0m\u001b[0;34m.\u001b[0m\u001b[0mimport_meta_graph\u001b[0m\u001b[0;34m(\u001b[0m\u001b[0;34m'./my_test_model-1000.meta'\u001b[0m\u001b[0;34m)\u001b[0m\u001b[0;34m\u001b[0m\u001b[0m\n\u001b[0;32m----> 6\u001b[0;31m \u001b[0msaver\u001b[0m\u001b[0;34m.\u001b[0m\u001b[0mrestore\u001b[0m\u001b[0;34m(\u001b[0m\u001b[0msess\u001b[0m\u001b[0;34m,\u001b[0m\u001b[0mtf\u001b[0m\u001b[0;34m.\u001b[0m\u001b[0mtrain\u001b[0m\u001b[0;34m.\u001b[0m\u001b[0mlatest_checkpoint\u001b[0m\u001b[0;34m(\u001b[0m\u001b[0;34m'./'\u001b[0m\u001b[0;34m)\u001b[0m\u001b[0;34m)\u001b[0m\u001b[0;34m\u001b[0m\u001b[0m\n\u001b[0m\u001b[1;32m      7\u001b[0m \u001b[0;34m\u001b[0m\u001b[0m\n\u001b[1;32m      8\u001b[0m \u001b[0;31m# Access saved Variables directly\u001b[0m\u001b[0;34m\u001b[0m\u001b[0;34m\u001b[0m\u001b[0m\n",
      "\u001b[0;32m/home/jacek/anaconda3/lib/python3.6/site-packages/tensorflow/python/training/saver.py\u001b[0m in \u001b[0;36mrestore\u001b[0;34m(self, sess, save_path)\u001b[0m\n\u001b[1;32m   1546\u001b[0m     \u001b[0mlogging\u001b[0m\u001b[0;34m.\u001b[0m\u001b[0minfo\u001b[0m\u001b[0;34m(\u001b[0m\u001b[0;34m\"Restoring parameters from %s\"\u001b[0m\u001b[0;34m,\u001b[0m \u001b[0msave_path\u001b[0m\u001b[0;34m)\u001b[0m\u001b[0;34m\u001b[0m\u001b[0m\n\u001b[1;32m   1547\u001b[0m     sess.run(self.saver_def.restore_op_name,\n\u001b[0;32m-> 1548\u001b[0;31m              {self.saver_def.filename_tensor_name: save_path})\n\u001b[0m\u001b[1;32m   1549\u001b[0m \u001b[0;34m\u001b[0m\u001b[0m\n\u001b[1;32m   1550\u001b[0m   \u001b[0;34m@\u001b[0m\u001b[0mstaticmethod\u001b[0m\u001b[0;34m\u001b[0m\u001b[0m\n",
      "\u001b[0;32m/home/jacek/anaconda3/lib/python3.6/site-packages/tensorflow/python/client/session.py\u001b[0m in \u001b[0;36mrun\u001b[0;34m(self, fetches, feed_dict, options, run_metadata)\u001b[0m\n\u001b[1;32m    787\u001b[0m     \u001b[0;32mtry\u001b[0m\u001b[0;34m:\u001b[0m\u001b[0;34m\u001b[0m\u001b[0m\n\u001b[1;32m    788\u001b[0m       result = self._run(None, fetches, feed_dict, options_ptr,\n\u001b[0;32m--> 789\u001b[0;31m                          run_metadata_ptr)\n\u001b[0m\u001b[1;32m    790\u001b[0m       \u001b[0;32mif\u001b[0m \u001b[0mrun_metadata\u001b[0m\u001b[0;34m:\u001b[0m\u001b[0;34m\u001b[0m\u001b[0m\n\u001b[1;32m    791\u001b[0m         \u001b[0mproto_data\u001b[0m \u001b[0;34m=\u001b[0m \u001b[0mtf_session\u001b[0m\u001b[0;34m.\u001b[0m\u001b[0mTF_GetBuffer\u001b[0m\u001b[0;34m(\u001b[0m\u001b[0mrun_metadata_ptr\u001b[0m\u001b[0;34m)\u001b[0m\u001b[0;34m\u001b[0m\u001b[0m\n",
      "\u001b[0;32m/home/jacek/anaconda3/lib/python3.6/site-packages/tensorflow/python/client/session.py\u001b[0m in \u001b[0;36m_run\u001b[0;34m(self, handle, fetches, feed_dict, options, run_metadata)\u001b[0m\n\u001b[1;32m    995\u001b[0m     \u001b[0;32mif\u001b[0m \u001b[0mfinal_fetches\u001b[0m \u001b[0;32mor\u001b[0m \u001b[0mfinal_targets\u001b[0m\u001b[0;34m:\u001b[0m\u001b[0;34m\u001b[0m\u001b[0m\n\u001b[1;32m    996\u001b[0m       results = self._do_run(handle, final_targets, final_fetches,\n\u001b[0;32m--> 997\u001b[0;31m                              feed_dict_string, options, run_metadata)\n\u001b[0m\u001b[1;32m    998\u001b[0m     \u001b[0;32melse\u001b[0m\u001b[0;34m:\u001b[0m\u001b[0;34m\u001b[0m\u001b[0m\n\u001b[1;32m    999\u001b[0m       \u001b[0mresults\u001b[0m \u001b[0;34m=\u001b[0m \u001b[0;34m[\u001b[0m\u001b[0;34m]\u001b[0m\u001b[0;34m\u001b[0m\u001b[0m\n",
      "\u001b[0;32m/home/jacek/anaconda3/lib/python3.6/site-packages/tensorflow/python/client/session.py\u001b[0m in \u001b[0;36m_do_run\u001b[0;34m(self, handle, target_list, fetch_list, feed_dict, options, run_metadata)\u001b[0m\n\u001b[1;32m   1130\u001b[0m     \u001b[0;32mif\u001b[0m \u001b[0mhandle\u001b[0m \u001b[0;32mis\u001b[0m \u001b[0;32mNone\u001b[0m\u001b[0;34m:\u001b[0m\u001b[0;34m\u001b[0m\u001b[0m\n\u001b[1;32m   1131\u001b[0m       return self._do_call(_run_fn, self._session, feed_dict, fetch_list,\n\u001b[0;32m-> 1132\u001b[0;31m                            target_list, options, run_metadata)\n\u001b[0m\u001b[1;32m   1133\u001b[0m     \u001b[0;32melse\u001b[0m\u001b[0;34m:\u001b[0m\u001b[0;34m\u001b[0m\u001b[0m\n\u001b[1;32m   1134\u001b[0m       return self._do_call(_prun_fn, self._session, handle, feed_dict,\n",
      "\u001b[0;32m/home/jacek/anaconda3/lib/python3.6/site-packages/tensorflow/python/client/session.py\u001b[0m in \u001b[0;36m_do_call\u001b[0;34m(self, fn, *args)\u001b[0m\n\u001b[1;32m   1150\u001b[0m         \u001b[0;32mexcept\u001b[0m \u001b[0mKeyError\u001b[0m\u001b[0;34m:\u001b[0m\u001b[0;34m\u001b[0m\u001b[0m\n\u001b[1;32m   1151\u001b[0m           \u001b[0;32mpass\u001b[0m\u001b[0;34m\u001b[0m\u001b[0m\n\u001b[0;32m-> 1152\u001b[0;31m       \u001b[0;32mraise\u001b[0m \u001b[0mtype\u001b[0m\u001b[0;34m(\u001b[0m\u001b[0me\u001b[0m\u001b[0;34m)\u001b[0m\u001b[0;34m(\u001b[0m\u001b[0mnode_def\u001b[0m\u001b[0;34m,\u001b[0m \u001b[0mop\u001b[0m\u001b[0;34m,\u001b[0m \u001b[0mmessage\u001b[0m\u001b[0;34m)\u001b[0m\u001b[0;34m\u001b[0m\u001b[0m\n\u001b[0m\u001b[1;32m   1153\u001b[0m \u001b[0;34m\u001b[0m\u001b[0m\n\u001b[1;32m   1154\u001b[0m   \u001b[0;32mdef\u001b[0m \u001b[0m_extend_graph\u001b[0m\u001b[0;34m(\u001b[0m\u001b[0mself\u001b[0m\u001b[0;34m)\u001b[0m\u001b[0;34m:\u001b[0m\u001b[0;34m\u001b[0m\u001b[0m\n",
      "\u001b[0;31mNotFoundError\u001b[0m: Key Variable not found in checkpoint\n\t [[Node: save/RestoreV2 = RestoreV2[dtypes=[DT_FLOAT], _device=\"/job:localhost/replica:0/task:0/cpu:0\"](_arg_save/Const_0_0, save/RestoreV2/tensor_names, save/RestoreV2/shape_and_slices)]]\n\nCaused by op 'save/RestoreV2', defined at:\n  File \"/home/jacek/anaconda3/lib/python3.6/runpy.py\", line 193, in _run_module_as_main\n    \"__main__\", mod_spec)\n  File \"/home/jacek/anaconda3/lib/python3.6/runpy.py\", line 85, in _run_code\n    exec(code, run_globals)\n  File \"/home/jacek/anaconda3/lib/python3.6/site-packages/ipykernel_launcher.py\", line 16, in <module>\n    app.launch_new_instance()\n  File \"/home/jacek/anaconda3/lib/python3.6/site-packages/traitlets/config/application.py\", line 658, in launch_instance\n    app.start()\n  File \"/home/jacek/anaconda3/lib/python3.6/site-packages/ipykernel/kernelapp.py\", line 477, in start\n    ioloop.IOLoop.instance().start()\n  File \"/home/jacek/anaconda3/lib/python3.6/site-packages/zmq/eventloop/ioloop.py\", line 177, in start\n    super(ZMQIOLoop, self).start()\n  File \"/home/jacek/anaconda3/lib/python3.6/site-packages/tornado/ioloop.py\", line 888, in start\n    handler_func(fd_obj, events)\n  File \"/home/jacek/anaconda3/lib/python3.6/site-packages/tornado/stack_context.py\", line 277, in null_wrapper\n    return fn(*args, **kwargs)\n  File \"/home/jacek/anaconda3/lib/python3.6/site-packages/zmq/eventloop/zmqstream.py\", line 440, in _handle_events\n    self._handle_recv()\n  File \"/home/jacek/anaconda3/lib/python3.6/site-packages/zmq/eventloop/zmqstream.py\", line 472, in _handle_recv\n    self._run_callback(callback, msg)\n  File \"/home/jacek/anaconda3/lib/python3.6/site-packages/zmq/eventloop/zmqstream.py\", line 414, in _run_callback\n    callback(*args, **kwargs)\n  File \"/home/jacek/anaconda3/lib/python3.6/site-packages/tornado/stack_context.py\", line 277, in null_wrapper\n    return fn(*args, **kwargs)\n  File \"/home/jacek/anaconda3/lib/python3.6/site-packages/ipykernel/kernelbase.py\", line 283, in dispatcher\n    return self.dispatch_shell(stream, msg)\n  File \"/home/jacek/anaconda3/lib/python3.6/site-packages/ipykernel/kernelbase.py\", line 235, in dispatch_shell\n    handler(stream, idents, msg)\n  File \"/home/jacek/anaconda3/lib/python3.6/site-packages/ipykernel/kernelbase.py\", line 399, in execute_request\n    user_expressions, allow_stdin)\n  File \"/home/jacek/anaconda3/lib/python3.6/site-packages/ipykernel/ipkernel.py\", line 196, in do_execute\n    res = shell.run_cell(code, store_history=store_history, silent=silent)\n  File \"/home/jacek/anaconda3/lib/python3.6/site-packages/ipykernel/zmqshell.py\", line 533, in run_cell\n    return super(ZMQInteractiveShell, self).run_cell(*args, **kwargs)\n  File \"/home/jacek/anaconda3/lib/python3.6/site-packages/IPython/core/interactiveshell.py\", line 2717, in run_cell\n    interactivity=interactivity, compiler=compiler, result=result)\n  File \"/home/jacek/anaconda3/lib/python3.6/site-packages/IPython/core/interactiveshell.py\", line 2821, in run_ast_nodes\n    if self.run_code(code, result):\n  File \"/home/jacek/anaconda3/lib/python3.6/site-packages/IPython/core/interactiveshell.py\", line 2881, in run_code\n    exec(code_obj, self.user_global_ns, self.user_ns)\n  File \"<ipython-input-2-48250861f1ff>\", line 5, in <module>\n    saver = tf.train.import_meta_graph('./model1.meta')\n  File \"/home/jacek/anaconda3/lib/python3.6/site-packages/tensorflow/python/training/saver.py\", line 1686, in import_meta_graph\n    **kwargs)\n  File \"/home/jacek/anaconda3/lib/python3.6/site-packages/tensorflow/python/framework/meta_graph.py\", line 504, in import_scoped_meta_graph\n    producer_op_list=producer_op_list)\n  File \"/home/jacek/anaconda3/lib/python3.6/site-packages/tensorflow/python/framework/importer.py\", line 311, in import_graph_def\n    op_def=op_def)\n  File \"/home/jacek/anaconda3/lib/python3.6/site-packages/tensorflow/python/framework/ops.py\", line 2506, in create_op\n    original_op=self._default_original_op, op_def=op_def)\n  File \"/home/jacek/anaconda3/lib/python3.6/site-packages/tensorflow/python/framework/ops.py\", line 1269, in __init__\n    self._traceback = _extract_stack()\n\nNotFoundError (see above for traceback): Key Variable not found in checkpoint\n\t [[Node: save/RestoreV2 = RestoreV2[dtypes=[DT_FLOAT], _device=\"/job:localhost/replica:0/task:0/cpu:0\"](_arg_save/Const_0_0, save/RestoreV2/tensor_names, save/RestoreV2/shape_and_slices)]]\n"
     ]
    }
   ],
   "source": [
    "import tensorflow as tf\n",
    "\n",
    "sess = tf.Session()    \n",
    "#First let's load meta graph and restore weights\n",
    "saver = tf.train.import_meta_graph('./my_test_model-1000.meta')\n",
    "saver.restore(sess, \"./my_test_model\")\n",
    "\n",
    "# Access saved Variables directly\n",
    "print(sess.run('bias:0'))\n",
    "# This will print 2, which is the value of bias that we saved\n",
    "\n",
    "\n",
    "# Now, let's access and create placeholders variables and\n",
    "# create feed-dict to feed new data\n",
    "\n",
    "graph = tf.get_default_graph()\n",
    "w1 = graph.get_tensor_by_name(\"w1:0\")\n",
    "w2 = graph.get_tensor_by_name(\"w2:0\")\n",
    "feed_dict ={w1:13.0,w2:17.0}\n",
    "\n",
    "#Now, access the op that you want to run. \n",
    "op_to_restore = graph.get_tensor_by_name(\"op_to_restore:0\")\n",
    "\n",
    "print(sess.run(op_to_restore,feed_dict))\n",
    "#This will print 60 which is calculated "
   ]
  },
  {
   "cell_type": "code",
   "execution_count": null,
   "metadata": {
    "collapsed": true
   },
   "outputs": [],
   "source": []
  }
 ],
 "metadata": {
  "kernelspec": {
   "display_name": "Python 3",
   "language": "python",
   "name": "python3"
  },
  "language_info": {
   "codemirror_mode": {
    "name": "ipython",
    "version": 3
   },
   "file_extension": ".py",
   "mimetype": "text/x-python",
   "name": "python",
   "nbconvert_exporter": "python",
   "pygments_lexer": "ipython3",
   "version": "3.6.1"
  }
 },
 "nbformat": 4,
 "nbformat_minor": 2
}
